Workbook

Sheet Dashboard
A1: Inventory & Supplier Dashboard: Corrib Medical Devices
A2: Snapshot 30-Sep-2026. All figures are live formulas; change the Assumptions sheet to run scenarios.
A4: Inventory value | D4: Excess stock value | G4: SKUs below safety stock | J4: SKUs to reorder now
A5: =SUM(Inventory_Policy!$AB$5:$AB$120) | D5: =SUM(Inventory_Policy!$AC$5:$AC$120) | G5: =COUNTIF(Inventory_Policy!$AA$5:$AA$120,"Below safety stock") | J5: =COUNTIF(Inventory_Policy!$AA$5:$AA$120,"Reorder now")
A7: Supplier OTIF (weighted) | D7: FY purchase variance | G7: of which price variance
A8: =Supplier_Scorecard!J17 | D8: =Budget_vs_Actual!D57 | G8: =Budget_vs_Actual!F57
A10: ABC classification | F10: Stock status | K10: ABC-XYZ matrix (SKU count)
A11: Class | B11: SKUs | C11: % of SKUs | D11: % of spend | F11: Status | G11: SKUs | H11: Stock value (€) | I11: Excess (€) | K11: ABC \ XYZ | L11: X stable | M11: Y variable | N11: Z erratic
A12: A | B12: =COUNTIF(Inventory_Policy!$L$5:$L$120,A12) | C12: =B12/SUM($B$12:$B$14) | D12: =SUMIF(Inventory_Policy!$L$5:$L$120,A12,Inventory_Policy!$J$5:$J$120)/SUM(Inventory_Policy!$J$5:$J$120) | F12: Below safety stock | G12: =COUNTIF(Inventory_Policy!$AA$5:$AA$120,F12) | H12: =SUMIF(Inventory_Policy!$AA$5:$AA$120,F12,Inventory_Policy!$AB$5:$AB$120) | I12: =SUMIF(Inventory_Policy!$AA$5:$AA$120,F12,Inventory_Policy!$AC$5:$AC$120) | K12: A | L12: =COUNTIF(Inventory_Policy!$N$5:$N$120,"AX") | M12: =COUNTIF(Inventory_Policy!$N$5:$N$120,"AY") | N12: =COUNTIF(Inventory_Policy!$N$5:$N$120,"AZ")
A13: B | B13: =COUNTIF(Inventory_Policy!$L$5:$L$120,A13) | C13: =B13/SUM($B$12:$B$14) | D13: =SUMIF(Inventory_Policy!$L$5:$L$120,A13,Inventory_Policy!$J$5:$J$120)/SUM(Inventory_Policy!$J$5:$J$120) | F13: Reorder now | G13: =COUNTIF(Inventory_Policy!$AA$5:$AA$120,F13) | H13: =SUMIF(Inventory_Policy!$AA$5:$AA$120,F13,Inventory_Policy!$AB$5:$AB$120) | I13: =SUMIF(Inventory_Policy!$AA$5:$AA$120,F13,Inventory_Policy!$AC$5:$AC$120) | K13: B | L13: =COUNTIF(Inventory_Policy!$N$5:$N$120,"BX") | M13: =COUNTIF(Inventory_Policy!$N$5:$N$120,"BY") | N13: =COUNTIF(Inventory_Policy!$N$5:$N$120,"BZ")
A14: C | B14: =COUNTIF(Inventory_Policy!$L$5:$L$120,A14) | C14: =B14/SUM($B$12:$B$14) | D14: =SUMIF(Inventory_Policy!$L$5:$L$120,A14,Inventory_Policy!$J$5:$J$120)/SUM(Inventory_Policy!$J$5:$J$120) | F14: Healthy | G14: =COUNTIF(Inventory_Policy!$AA$5:$AA$120,F14) | H14: =SUMIF(Inventory_Policy!$AA$5:$AA$120,F14,Inventory_Policy!$AB$5:$AB$120) | I14: =SUMIF(Inventory_Policy!$AA$5:$AA$120,F14,Inventory_Policy!$AC$5:$AC$120) | K14: C | L14: =COUNTIF(Inventory_Policy!$N$5:$N$120,"CX") | M14: =COUNTIF(Inventory_Policy!$N$5:$N$120,"CY") | N14: =COUNTIF(Inventory_Policy!$N$5:$N$120,"CZ")
F15: Excess | G15: =COUNTIF(Inventory_Policy!$AA$5:$AA$120,F15) | H15: =SUMIF(Inventory_Policy!$AA$5:$AA$120,F15,Inventory_Policy!$AB$5:$AB$120) | I15: =SUMIF(Inventory_Policy!$AA$5:$AA$120,F15,Inventory_Policy!$AC$5:$AC$120)
A17: Top 10 excess stock (€) | F17: Top 10 shortfall vs reorder point (€) | K17: SKU lookup: pick a SKU
A18: SKU | B18: Description | C18: Supplier | D18: Value (€) | F18: SKU | G18: Description | H18: Supplier | I18: Value (€) | K18: Selected SKU | L18: CMD-0001
A19: =IF(D19=0,"",INDEX(Inventory_Policy!$A$5:$A$120,MATCH(D19,Inventory_Policy!$AC$5:$AC$120,0))) | B19: =IF(D19=0,"",INDEX(Inventory_Policy!$B$5:$B$120,MATCH(D19,Inventory_Policy!$AC$5:$AC$120,0))) | C19: =IF(D19=0,"",INDEX(Inventory_Policy!$D$5:$D$120,MATCH(D19,Inventory_Policy!$AC$5:$AC$120,0))) | D19: =LARGE(Inventory_Policy!$AC$5:$AC$120,1) | F19: =IF(I19=0,"",INDEX(Inventory_Policy!$A$5:$A$120,MATCH(I19,Inventory_Policy!$AE$5:$AE$120,0))) | G19: =IF(I19=0,"",INDEX(Inventory_Policy!$B$5:$B$120,MATCH(I19,Inventory_Policy!$AE$5:$AE$120,0))) | H19: =IF(I19=0,"",INDEX(Inventory_Policy!$D$5:$D$120,MATCH(I19,Inventory_Policy!$AE$5:$AE$120,0))) | I19: =LARGE(Inventory_Policy!$AE$5:$AE$120,1) | K19: Description | L19: =INDEX(Inventory_Policy!$B$5:$B$120,MATCH($L$18,Inventory_Policy!$A$5:$A$120,0))
A20: =IF(D20=0,"",INDEX(Inventory_Policy!$A$5:$A$120,MATCH(D20,Inventory_Policy!$AC$5:$AC$120,0))) | B20: =IF(D20=0,"",INDEX(Inventory_Policy!$B$5:$B$120,MATCH(D20,Inventory_Policy!$AC$5:$AC$120,0))) | C20: =IF(D20=0,"",INDEX(Inventory_Policy!$D$5:$D$120,MATCH(D20,Inventory_Policy!$AC$5:$AC$120,0))) | D20: =LARGE(Inventory_Policy!$AC$5:$AC$120,2) | F20: =IF(I20=0,"",INDEX(Inventory_Policy!$A$5:$A$120,MATCH(I20,Inventory_Policy!$AE$5:$AE$120,0))) | G20: =IF(I20=0,"",INDEX(Inventory_Policy!$B$5:$B$120,MATCH(I20,Inventory_Policy!$AE$5:$AE$120,0))) | H20: =IF(I20=0,"",INDEX(Inventory_Policy!$D$5:$D$120,MATCH(I20,Inventory_Policy!$AE$5:$AE$120,0))) | I20: =LARGE(Inventory_Policy!$AE$5:$AE$120,2) | K20: Category | L20: =INDEX(Inventory_Policy!$C$5:$C$120,MATCH($L$18,Inventory_Policy!$A$5:$A$120,0))
A21: =IF(D21=0,"",INDEX(Inventory_Policy!$A$5:$A$120,MATCH(D21,Inventory_Policy!$AC$5:$AC$120,0))) | B21: =IF(D21=0,"",INDEX(Inventory_Policy!$B$5:$B$120,MATCH(D21,Inventory_Policy!$AC$5:$AC$120,0))) | C21: =IF(D21=0,"",INDEX(Inventory_Policy!$D$5:$D$120,MATCH(D21,Inventory_Policy!$AC$5:$AC$120,0))) | D21: =LARGE(Inventory_Policy!$AC$5:$AC$120,3) | F21: =IF(I21=0,"",INDEX(Inventory_Policy!$A$5:$A$120,MATCH(I21,Inventory_Policy!$AE$5:$AE$120,0))) | G21: =IF(I21=0,"",INDEX(Inventory_Policy!$B$5:$B$120,MATCH(I21,Inventory_Policy!$AE$5:$AE$120,0))) | H21: =IF(I21=0,"",INDEX(Inventory_Policy!$D$5:$D$120,MATCH(I21,Inventory_Policy!$AE$5:$AE$120,0))) | I21: =LARGE(Inventory_Policy!$AE$5:$AE$120,3) | K21: Supplier | L21: =INDEX(Inventory_Policy!$D$5:$D$120,MATCH($L$18,Inventory_Policy!$A$5:$A$120,0))
A22: =IF(D22=0,"",INDEX(Inventory_Policy!$A$5:$A$120,MATCH(D22,Inventory_Policy!$AC$5:$AC$120,0))) | B22: =IF(D22=0,"",INDEX(Inventory_Policy!$B$5:$B$120,MATCH(D22,Inventory_Policy!$AC$5:$AC$120,0))) | C22: =IF(D22=0,"",INDEX(Inventory_Policy!$D$5:$D$120,MATCH(D22,Inventory_Policy!$AC$5:$AC$120,0))) | D22: =LARGE(Inventory_Policy!$AC$5:$AC$120,4) | F22: =IF(I22=0,"",INDEX(Inventory_Policy!$A$5:$A$120,MATCH(I22,Inventory_Policy!$AE$5:$AE$120,0))) | G22: =IF(I22=0,"",INDEX(Inventory_Policy!$B$5:$B$120,MATCH(I22,Inventory_Policy!$AE$5:$AE$120,0))) | H22: =IF(I22=0,"",INDEX(Inventory_Policy!$D$5:$D$120,MATCH(I22,Inventory_Policy!$AE$5:$AE$120,0))) | I22: =LARGE(Inventory_Policy!$AE$5:$AE$120,4) | K22: ABC-XYZ | L22: =INDEX(Inventory_Policy!$N$5:$N$120,MATCH($L$18,Inventory_Policy!$A$5:$A$120,0))
A23: =IF(D23=0,"",INDEX(Inventory_Policy!$A$5:$A$120,MATCH(D23,Inventory_Policy!$AC$5:$AC$120,0))) | B23: =IF(D23=0,"",INDEX(Inventory_Policy!$B$5:$B$120,MATCH(D23,Inventory_Policy!$AC$5:$AC$120,0))) | C23: =IF(D23=0,"",INDEX(Inventory_Policy!$D$5:$D$120,MATCH(D23,Inventory_Policy!$AC$5:$AC$120,0))) | D23: =LARGE(Inventory_Policy!$AC$5:$AC$120,5) | F23: =IF(I23=0,"",INDEX(Inventory_Policy!$A$5:$A$120,MATCH(I23,Inventory_Policy!$AE$5:$AE$120,0))) | G23: =IF(I23=0,"",INDEX(Inventory_Policy!$B$5:$B$120,MATCH(I23,Inventory_Policy!$AE$5:$AE$120,0))) | H23: =IF(I23=0,"",INDEX(Inventory_Policy!$D$5:$D$120,MATCH(I23,Inventory_Policy!$AE$5:$AE$120,0))) | I23: =LARGE(Inventory_Policy!$AE$5:$AE$120,5) | K23: Avg monthly demand | L23: =INDEX(Inventory_Policy!$G$5:$G$120,MATCH($L$18,Inventory_Policy!$A$5:$A$120,0))
A24: =IF(D24=0,"",INDEX(Inventory_Policy!$A$5:$A$120,MATCH(D24,Inventory_Policy!$AC$5:$AC$120,0))) | B24: =IF(D24=0,"",INDEX(Inventory_Policy!$B$5:$B$120,MATCH(D24,Inventory_Policy!$AC$5:$AC$120,0))) | C24: =IF(D24=0,"",INDEX(Inventory_Policy!$D$5:$D$120,MATCH(D24,Inventory_Policy!$AC$5:$AC$120,0))) | D24: =LARGE(Inventory_Policy!$AC$5:$AC$120,6) | F24: =IF(I24=0,"",INDEX(Inventory_Policy!$A$5:$A$120,MATCH(I24,Inventory_Policy!$AE$5:$AE$120,0))) | G24: =IF(I24=0,"",INDEX(Inventory_Policy!$B$5:$B$120,MATCH(I24,Inventory_Policy!$AE$5:$AE$120,0))) | H24: =IF(I24=0,"",INDEX(Inventory_Policy!$D$5:$D$120,MATCH(I24,Inventory_Policy!$AE$5:$AE$120,0))) | I24: =LARGE(Inventory_Policy!$AE$5:$AE$120,6) | K24: Actual lead time (days) | L24: =INDEX(Inventory_Policy!$Q$5:$Q$120,MATCH($L$18,Inventory_Policy!$A$5:$A$120,0))
A25: =IF(D25=0,"",INDEX(Inventory_Policy!$A$5:$A$120,MATCH(D25,Inventory_Policy!$AC$5:$AC$120,0))) | B25: =IF(D25=0,"",INDEX(Inventory_Policy!$B$5:$B$120,MATCH(D25,Inventory_Policy!$AC$5:$AC$120,0))) | C25: =IF(D25=0,"",INDEX(Inventory_Policy!$D$5:$D$120,MATCH(D25,Inventory_Policy!$AC$5:$AC$120,0))) | D25: =LARGE(Inventory_Policy!$AC$5:$AC$120,7) | F25: =IF(I25=0,"",INDEX(Inventory_Policy!$A$5:$A$120,MATCH(I25,Inventory_Policy!$AE$5:$AE$120,0))) | G25: =IF(I25=0,"",INDEX(Inventory_Policy!$B$5:$B$120,MATCH(I25,Inventory_Policy!$AE$5:$AE$120,0))) | H25: =IF(I25=0,"",INDEX(Inventory_Policy!$D$5:$D$120,MATCH(I25,Inventory_Policy!$AE$5:$AE$120,0))) | I25: =LARGE(Inventory_Policy!$AE$5:$AE$120,7) | K25: Safety stock | L25: =INDEX(Inventory_Policy!$S$5:$S$120,MATCH($L$18,Inventory_Policy!$A$5:$A$120,0))
A26: =IF(D26=0,"",INDEX(Inventory_Policy!$A$5:$A$120,MATCH(D26,Inventory_Policy!$AC$5:$AC$120,0))) | B26: =IF(D26=0,"",INDEX(Inventory_Policy!$B$5:$B$120,MATCH(D26,Inventory_Policy!$AC$5:$AC$120,0))) | C26: =IF(D26=0,"",INDEX(Inventory_Policy!$D$5:$D$120,MATCH(D26,Inventory_Policy!$AC$5:$AC$120,0))) | D26: =LARGE(Inventory_Policy!$AC$5:$AC$120,8) | F26: =IF(I26=0,"",INDEX(Inventory_Policy!$A$5:$A$120,MATCH(I26,Inventory_Policy!$AE$5:$AE$120,0))) | G26: =IF(I26=0,"",INDEX(Inventory_Policy!$B$5:$B$120,MATCH(I26,Inventory_Policy!$AE$5:$AE$120,0))) | H26: =IF(I26=0,"",INDEX(Inventory_Policy!$D$5:$D$120,MATCH(I26,Inventory_Policy!$AE$5:$AE$120,0))) | I26: =LARGE(Inventory_Policy!$AE$5:$AE$120,8) | K26: Reorder point | L26: =INDEX(Inventory_Policy!$T$5:$T$120,MATCH($L$18,Inventory_Policy!$A$5:$A$120,0))
A27: =IF(D27=0,"",INDEX(Inventory_Policy!$A$5:$A$120,MATCH(D27,Inventory_Policy!$AC$5:$AC$120,0))) | B27: =IF(D27=0,"",INDEX(Inventory_Policy!$B$5:$B$120,MATCH(D27,Inventory_Policy!$AC$5:$AC$120,0))) | C27: =IF(D27=0,"",INDEX(Inventory_Policy!$D$5:$D$120,MATCH(D27,Inventory_Policy!$AC$5:$AC$120,0))) | D27: =LARGE(Inventory_Policy!$AC$5:$AC$120,9) | F27: =IF(I27=0,"",INDEX(Inventory_Policy!$A$5:$A$120,MATCH(I27,Inventory_Policy!$AE$5:$AE$120,0))) | G27: =IF(I27=0,"",INDEX(Inventory_Policy!$B$5:$B$120,MATCH(I27,Inventory_Policy!$AE$5:$AE$120,0))) | H27: =IF(I27=0,"",INDEX(Inventory_Policy!$D$5:$D$120,MATCH(I27,Inventory_Policy!$AE$5:$AE$120,0))) | I27: =LARGE(Inventory_Policy!$AE$5:$AE$120,9) | K27: Order quantity | L27: =INDEX(Inventory_Policy!$U$5:$U$120,MATCH($L$18,Inventory_Policy!$A$5:$A$120,0))
A28: =IF(D28=0,"",INDEX(Inventory_Policy!$A$5:$A$120,MATCH(D28,Inventory_Policy!$AC$5:$AC$120,0))) | B28: =IF(D28=0,"",INDEX(Inventory_Policy!$B$5:$B$120,MATCH(D28,Inventory_Policy!$AC$5:$AC$120,0))) | C28: =IF(D28=0,"",INDEX(Inventory_Policy!$D$5:$D$120,MATCH(D28,Inventory_Policy!$AC$5:$AC$120,0))) | D28: =LARGE(Inventory_Policy!$AC$5:$AC$120,10) | F28: =IF(I28=0,"",INDEX(Inventory_Policy!$A$5:$A$120,MATCH(I28,Inventory_Policy!$AE$5:$AE$120,0))) | G28: =IF(I28=0,"",INDEX(Inventory_Policy!$B$5:$B$120,MATCH(I28,Inventory_Policy!$AE$5:$AE$120,0))) | H28: =IF(I28=0,"",INDEX(Inventory_Policy!$D$5:$D$120,MATCH(I28,Inventory_Policy!$AE$5:$AE$120,0))) | I28: =LARGE(Inventory_Policy!$AE$5:$AE$120,10) | K28: On hand | L28: =INDEX(Inventory_Policy!$V$5:$V$120,MATCH($L$18,Inventory_Policy!$A$5:$A$120,0))
K29: On order | L29: =INDEX(Inventory_Policy!$W$5:$W$120,MATCH($L$18,Inventory_Policy!$A$5:$A$120,0))
K30: Days of cover | L30: =INDEX(Inventory_Policy!$Y$5:$Y$120,MATCH($L$18,Inventory_Policy!$A$5:$A$120,0))
K31: Status | L31: =INDEX(Inventory_Policy!$AA$5:$AA$120,MATCH($L$18,Inventory_Policy!$A$5:$A$120,0))
K32: Suggested order qty | L32: =INDEX(Inventory_Policy!$AD$5:$AD$120,MATCH($L$18,Inventory_Policy!$A$5:$A$120,0))
A55: Chart data (feeds the charts above)
A56: Supplier | B56: OTIF % | F56: Month | G56: Budget (€) | H56: Actual (€)
A57: =Supplier_Scorecard!B5 | B57: =Supplier_Scorecard!J5 | F57: 2025-10 | G57: =Budget_vs_Actual!B15 | H57: =Budget_vs_Actual!B29
A58: =Supplier_Scorecard!B6 | B58: =Supplier_Scorecard!J6 | F58: 2025-11 | G58: =Budget_vs_Actual!C15 | H58: =Budget_vs_Actual!C29
A59: =Supplier_Scorecard!B7 | B59: =Supplier_Scorecard!J7 | F59: 2025-12 | G59: =Budget_vs_Actual!D15 | H59: =Budget_vs_Actual!D29
A60: =Supplier_Scorecard!B8 | B60: =Supplier_Scorecard!J8 | F60: 2026-01 | G60: =Budget_vs_Actual!E15 | H60: =Budget_vs_Actual!E29
A61: =Supplier_Scorecard!B9 | B61: =Supplier_Scorecard!J9 | F61: 2026-02 | G61: =Budget_vs_Actual!F15 | H61: =Budget_vs_Actual!F29
A62: =Supplier_Scorecard!B10 | B62: =Supplier_Scorecard!J10 | F62: 2026-03 | G62: =Budget_vs_Actual!G15 | H62: =Budget_vs_Actual!G29
A63: =Supplier_Scorecard!B11 | B63: =Supplier_Scorecard!J11 | F63: 2026-04 | G63: =Budget_vs_Actual!H15 | H63: =Budget_vs_Actual!H29
A64: =Supplier_Scorecard!B12 | B64: =Supplier_Scorecard!J12 | F64: 2026-05 | G64: =Budget_vs_Actual!I15 | H64: =Budget_vs_Actual!I29
A65: =Supplier_Scorecard!B13 | B65: =Supplier_Scorecard!J13 | F65: 2026-06 | G65: =Budget_vs_Actual!J15 | H65: =Budget_vs_Actual!J29
A66: =Supplier_Scorecard!B14 | B66: =Supplier_Scorecard!J14 | F66: 2026-07 | G66: =Budget_vs_Actual!K15 | H66: =Budget_vs_Actual!K29
...

Sheet README
A1: Corrib Medical Devices: Component Inventory & Supplier Model
A2: Simulated data for a fictional Galway medtech manufacturer (patient monitors, wearable ECG patches, infusion pumps)
A4: Purpose | B4: Set inventory policy (safety stock, reorder point, order quantity) for 116 electronic and packaging components, find excess and shortage risk, score suppliers, and explain budget variance.
A5: How to use | B5: Change any yellow cell on the 'Assumptions' sheet (service levels, holding cost, thresholds). Every analysis sheet recalculates. Use the SKU selector on the 'Dashboard' to inspect any part.
A6: Sheets | B6: Dashboard: KPIs, charts, SKU lookup | Inventory_Policy: ABC/XYZ, safety stock, ROP, EOQ, status | Supplier_Scorecard: OTIF, rejects, lead times | Budget_vs_Actual: monthly variance with price/volume split | Assumptions | Data sheets: Items, Demand, PO_Lines, Stock_Snapshot, Suppliers
A7: Colour legend | B7: Blue text = hard-coded input | Black text = formula | Yellow fill = key assumption you can change
A8: Method | B8: ABC by 12-month spend (Pareto). XYZ by coefficient of variation of monthly demand. Safety stock = z x sqrt(LT x sd_demand^2 + demand^2 x sd_LT^2) using actual supplier lead times. ROP = demand during lead time + safety stock. Order qty = largest of EOQ (sqrt(2 x annual demand x order cost / holding cost per unit)), supplier MOQ and minimum order cover. Excess = stock above safety stock + one order quantity.
A9: Data | B9: All data is simulated (see src/generate_data.py) and the company is fictional. Snapshot date 30-Sep-2026; 24 months of consumption; 2,026 purchase order lines.

Sheet Inventory_Policy
A1: Inventory Policy by SKU
A2: ABC/XYZ classification, safety stock, reorder point, EOQ and stock status. All cells are formulas driven by the Assumptions sheet.
A4: SKU | B4: Description | C4: Category | D4: Supplier | E4: Unit cost (€) | F4: Annual usage (units) | G4: Avg monthly demand | H4: Std dev monthly | I4: CV | J4: Annual spend (€) | K4: Cumulative spend % | L4: ABC | M4: XYZ | N4: ABC-XYZ | O4: Service level | P4: z | Q4: Avg actual lead time (days) | R4: Lead time std dev (days) | S4: Safety stock (units) | T4: Reorder point (units) | U4: Order qty (EOQ, MOQ, min cover) | V4: On hand (units) | W4: On order (units) | X4: Inventory position | Y4: Days of cover | Z4: Max stock (SS + order qty) | AA4: Stock status | AB4: Stock value (€) | AC4: Excess value (€) | AD4: Suggested order qty | AE4: Shortfall vs ROP (€) | AF4: Oldest lot expiry | AG4: Expiry flag
A5: CMD-0001 | B5: =INDEX(Items!$B$2:$B$117,MATCH($A5,Items!$A$2:$A$117,0)) | C5: =INDEX(Items!$C$2:$C$117,MATCH($A5,Items!$A$2:$A$117,0)) | D5: =INDEX(Items!$D$2:$D$117,MATCH($A5,Items!$A$2:$A$117,0)) | E5: =INDEX(Items!$E$2:$E$117,MATCH($A5,Items!$A$2:$A$117,0)) | F5: =SUM(INDEX(Demand!$N$2:$Y$117,MATCH($A5,Demand!$A$2:$A$117,0),0)) | G5: =F5/12 | H5: =STDEV(INDEX(Demand!$N$2:$Y$117,MATCH($A5,Demand!$A$2:$A$117,0),0)) | I5: =IF(G5>0,H5/G5,0) | J5: =F5*E5 | K5: =SUMIF($J$5:$J$120,">="&J5)/SUM($J$5:$J$120) | L5: =IF(K5<=Assumptions!$B$7,"A",IF(K5<=Assumptions!$B$8,"B","C")) | M5: =IF(I5<=Assumptions!$B$9,"X",IF(I5<=Assumptions!$B$10,"Y","Z")) | N5: =L5&M5 | O5: =INDEX(Assumptions!$F$4:$F$6,MATCH(L5,Assumptions!$E$4:$E$6,0)) | P5: =NORMSINV(O5) | Q5: =IFERROR(AVERAGEIFS(PO_Lines!$R$2:$R$2025,PO_Lines!$B$2:$B$2025,$A5,PO_Lines!$Q$2:$Q$2025,1),INDEX(Items!$F$2:$F$117,MATCH($A5,Items!$A$2:$A$117,0))) | R5: =IFERROR(SQRT(SUMPRODUCT((PO_Lines!$B$2:$B$2025=$A5)*PO_Lines!$Q$2:$Q$2025*(PO_Lines!$R$2:$R$2025-Q5)^2)/(COUNTIFS(PO_Lines!$B$2:$B$2025,$A5,PO_Lines!$Q$2:$Q$2025,1)-1)),0) | S5: =ROUNDUP(P5*SQRT((Q5/Assumptions!$B$11)*H5^2+G5^2*(R5/Assumptions!$B$11)^2),0) | T5: =ROUNDUP(G5*Q5/Assumptions!$B$11+S5,0) | U5: =ROUNDUP(MAX(INDEX(Items!$G$2:$G$117,MATCH($A5,Items!$A$2:$A$117,0)),SQRT(2*F5*Assumptions!$B$5/(Assumptions!$B$6*E5)),G5*Assumptions!$B$16),0) | V5: =INDEX(Stock_Snapshot!$B$2:$B$117,MATCH($A5,Stock_Snapshot!$A$2:$A$117,0)) | W5: =INDEX(Stock_Snapshot!$C$2:$C$117,MATCH($A5,Stock_Snapshot!$A$2:$A$117,0)) | X5: =V5+W5 | Y5: =IF(G5>0,V5/(G5/Assumptions!$B$11),999) | Z5: =S5+U5 | AA5: =IF(V5<S5,"Below safety stock",IF(X5<=T5,"Reorder now",IF(V5>Z5,"Excess","Healthy"))) | AB5: =V5*E5 | AC5: =MAX(0,V5-Z5)*E5 | AD5: =IF(X5<=T5,ROUNDUP(T5+U5-X5,0),0) | AE5: =MAX(0,T5-X5)*E5 | AF5: =IF(INDEX(Stock_Snapshot!$D$2:$D$117,MATCH($A5,Stock_Snapshot!$A$2:$A$117,0))="","",INDEX(Stock_Snapshot!$D$2:$D$117,MATCH($A5,Stock_Snapshot!$A$2:$A$117,0))) | AG5: =IF(AF5="","",IF(AF5<=EDATE(Assumptions!$B$4,Assumptions!$B$12),"Expires < "&Assumptions!$B$12&" m","OK"))
A6: CMD-0002 | B6: =INDEX(Items!$B$2:$B$117,MATCH($A6,Items!$A$2:$A$117,0)) | C6: =INDEX(Items!$C$2:$C$117,MATCH($A6,Items!$A$2:$A$117,0)) | D6: =INDEX(Items!$D$2:$D$117,MATCH($A6,Items!$A$2:$A$117,0)) | E6: =INDEX(Items!$E$2:$E$117,MATCH($A6,Items!$A$2:$A$117,0)) | F6: =SUM(INDEX(Demand!$N$2:$Y$117,MATCH($A6,Demand!$A$2:$A$117,0),0)) | G6: =F6/12 | H6: =STDEV(INDEX(Demand!$N$2:$Y$117,MATCH($A6,Demand!$A$2:$A$117,0),0)) | I6: =IF(G6>0,H6/G6,0) | J6: =F6*E6 | K6: =SUMIF($J$5:$J$120,">="&J6)/SUM($J$5:$J$120) | L6: =IF(K6<=Assumptions!$B$7,"A",IF(K6<=Assumptions!$B$8,"B","C")) | M6: =IF(I6<=Assumptions!$B$9,"X",IF(I6<=Assumptions!$B$10,"Y","Z")) | N6: =L6&M6 | O6: =INDEX(Assumptions!$F$4:$F$6,MATCH(L6,Assumptions!$E$4:$E$6,0)) | P6: =NORMSINV(O6) | Q6: =IFERROR(AVERAGEIFS(PO_Lines!$R$2:$R$2025,PO_Lines!$B$2:$B$2025,$A6,PO_Lines!$Q$2:$Q$2025,1),INDEX(Items!$F$2:$F$117,MATCH($A6,Items!$A$2:$A$117,0))) | R6: =IFERROR(SQRT(SUMPRODUCT((PO_Lines!$B$2:$B$2025=$A6)*PO_Lines!$Q$2:$Q$2025*(PO_Lines!$R$2:$R$2025-Q6)^2)/(COUNTIFS(PO_Lines!$B$2:$B$2025,$A6,PO_Lines!$Q$2:$Q$2025,1)-1)),0) | S6: =ROUNDUP(P6*SQRT((Q6/Assumptions!$B$11)*H6^2+G6^2*(R6/Assumptions!$B$11)^2),0) | T6: =ROUNDUP(G6*Q6/Assumptions!$B$11+S6,0) | U6: =ROUNDUP(MAX(INDEX(Items!$G$2:$G$117,MATCH($A6,Items!$A$2:$A$117,0)),SQRT(2*F6*Assumptions!$B$5/(Assumptions!$B$6*E6)),G6*Assumptions!$B$16),0) | V6: =INDEX(Stock_Snapshot!$B$2:$B$117,MATCH($A6,Stock_Snapshot!$A$2:$A$117,0)) | W6: =INDEX(Stock_Snapshot!$C$2:$C$117,MATCH($A6,Stock_Snapshot!$A$2:$A$117,0)) | X6: =V6+W6 | Y6: =IF(G6>0,V6/(G6/Assumptions!$B$11),999) | Z6: =S6+U6 | AA6: =IF(V6<S6,"Below safety stock",IF(X6<=T6,"Reorder now",IF(V6>Z6,"Excess","Healthy"))) | AB6: =V6*E6 | AC6: =MAX(0,V6-Z6)*E6 | AD6: =IF(X6<=T6,ROUNDUP(T6+U6-X6,0),0) | AE6: =MAX(0,T6-X6)*E6 | AF6: =IF(INDEX(Stock_Snapshot!$D$2:$D$117,MATCH($A6,Stock_Snapshot!$A$2:$A$117,0))="","",INDEX(Stock_Snapshot!$D$2:$D$117,MATCH($A6,Stock_Snapshot!$A$2:$A$117,0))) | AG6: =IF(AF6="","",IF(AF6<=EDATE(Assumptions!$B$4,Assumptions!$B$12),"Expires < "&Assumptions!$B$12&" m","OK"))
A7: CMD-0003 | B7: =INDEX(Items!$B$2:$B$117,MATCH($A7,Items!$A$2:$A$117,0)) | C7: =INDEX(Items!$C$2:$C$117,MATCH($A7,Items!$A$2:$A$117,0)) | D7: =INDEX(Items!$D$2:$D$117,MATCH($A7,Items!$A$2:$A$117,0)) | E7: =INDEX(Items!$E$2:$E$117,MATCH($A7,Items!$A$2:$A$117,0)) | F7: =SUM(INDEX(Demand!$N$2:$Y$117,MATCH($A7,Demand!$A$2:$A$117,0),0)) | G7: =F7/12 | H7: =STDEV(INDEX(Demand!$N$2:$Y$117,MATCH($A7,Demand!$A$2:$A$117,0),0)) | I7: =IF(G7>0,H7/G7,0) | J7: =F7*E7 | K7: =SUMIF($J$5:$J$120,">="&J7)/SUM($J$5:$J$120) | L7: =IF(K7<=Assumptions!$B$7,"A",IF(K7<=Assumptions!$B$8,"B","C")) | M7: =IF(I7<=Assumptions!$B$9,"X",IF(I7<=Assumptions!$B$10,"Y","Z")) | N7: =L7&M7 | O7: =INDEX(Assumptions!$F$4:$F$6,MATCH(L7,Assumptions!$E$4:$E$6,0)) | P7: =NORMSINV(O7) | Q7: =IFERROR(AVERAGEIFS(PO_Lines!$R$2:$R$2025,PO_Lines!$B$2:$B$2025,$A7,PO_Lines!$Q$2:$Q$2025,1),INDEX(Items!$F$2:$F$117,MATCH($A7,Items!$A$2:$A$117,0))) | R7: =IFERROR(SQRT(SUMPRODUCT((PO_Lines!$B$2:$B$2025=$A7)*PO_Lines!$Q$2:$Q$2025*(PO_Lines!$R$2:$R$2025-Q7)^2)/(COUNTIFS(PO_Lines!$B$2:$B$2025,$A7,PO_Lines!$Q$2:$Q$2025,1)-1)),0) | S7: =ROUNDUP(P7*SQRT((Q7/Assumptions!$B$11)*H7^2+G7^2*(R7/Assumptions!$B$11)^2),0) | T7: =ROUNDUP(G7*Q7/Assumptions!$B$11+S7,0) | U7: =ROUNDUP(MAX(INDEX(Items!$G$2:$G$117,MATCH($A7,Items!$A$2:$A$117,0)),SQRT(2*F7*Assumptions!$B$5/(Assumptions!$B$6*E7)),G7*Assumptions!$B$16),0) | V7: =INDEX(Stock_Snapshot!$B$2:$B$117,MATCH($A7,Stock_Snapshot!$A$2:$A$117,0)) | W7: =INDEX(Stock_Snapshot!$C$2:$C$117,MATCH($A7,Stock_Snapshot!$A$2:$A$117,0)) | X7: =V7+W7 | Y7: =IF(G7>0,V7/(G7/Assumptions!$B$11),999) | Z7: =S7+U7 | AA7: =IF(V7<S7,"Below safety stock",IF(X7<=T7,"Reorder now",IF(V7>Z7,"Excess","Healthy"))) | AB7: =V7*E7 | AC7: =MAX(0,V7-Z7)*E7 | AD7: =IF(X7<=T7,ROUNDUP(T7+U7-X7,0),0) | AE7: =MAX(0,T7-X7)*E7 | AF7: =IF(INDEX(Stock_Snapshot!$D$2:$D$117,MATCH($A7,Stock_Snapshot!$A$2:$A$117,0))="","",INDEX(Stock_Snapshot!$D$2:$D$117,MATCH($A7,Stock_Snapshot!$A$2:$A$117,0))) | AG7: =IF(AF7="","",IF(AF7<=EDATE(Assumptions!$B$4,Assumptions!$B$12),"Expires < "&Assumptions!$B$12&" m","OK"))
A8: CMD-0004 | B8: =INDEX(Items!$B$2:$B$117,MATCH($A8,Items!$A$2:$A$117,0)) | C8: =INDEX(Items!$C$2:$C$117,MATCH($A8,Items!$A$2:$A$117,0)) | D8: =INDEX(Items!$D$2:$D$117,MATCH($A8,Items!$A$2:$A$117,0)) | E8: =INDEX(Items!$E$2:$E$117,MATCH($A8,Items!$A$2:$A$117,0)) | F8: =SUM(INDEX(Demand!$N$2:$Y$117,MATCH($A8,Demand!$A$2:$A$117,0),0)) | G8: =F8/12 | H8: =STDEV(INDEX(Demand!$N$2:$Y$117,MATCH($A8,Demand!$A$2:$A$117,0),0)) | I8: =IF(G8>0,H8/G8,0) | J8: =F8*E8 | K8: =SUMIF($J$5:$J$120,">="&J8)/SUM($J$5:$J$120) | L8: =IF(K8<=Assumptions!$B$7,"A",IF(K8<=Assumptions!$B$8,"B","C")) | M8: =IF(I8<=Assumptions!$B$9,"X",IF(I8<=Assumptions!$B$10,"Y","Z")) | N8: =L8&M8 | O8: =INDEX(Assumptions!$F$4:$F$6,MATCH(L8,Assumptions!$E$4:$E$6,0)) | P8: =NORMSINV(O8) | Q8: =IFERROR(AVERAGEIFS(PO_Lines!$R$2:$R$2025,PO_Lines!$B$2:$B$2025,$A8,PO_Lines!$Q$2:$Q$2025,1),INDEX(Items!$F$2:$F$117,MATCH($A8,Items!$A$2:$A$117,0))) | R8: =IFERROR(SQRT(SUMPRODUCT((PO_Lines!$B$2:$B$2025=$A8)*PO_Lines!$Q$2:$Q$2025*(PO_Lines!$R$2:$R$2025-Q8)^2)/(COUNTIFS(PO_Lines!$B$2:$B$2025,$A8,PO_Lines!$Q$2:$Q$2025,1)-1)),0) | S8: =ROUNDUP(P8*SQRT((Q8/Assumptions!$B$11)*H8^2+G8^2*(R8/Assumptions!$B$11)^2),0) | T8: =ROUNDUP(G8*Q8/Assumptions!$B$11+S8,0) | U8: =ROUNDUP(MAX(INDEX(Items!$G$2:$G$117,MATCH($A8,Items!$A$2:$A$117,0)),SQRT(2*F8*Assumptions!$B$5/(Assumptions!$B$6*E8)),G8*Assumptions!$B$16),0) | V8: =INDEX(Stock_Snapshot!$B$2:$B$117,MATCH($A8,Stock_Snapshot!$A$2:$A$117,0)) | W8: =INDEX(Stock_Snapshot!$C$2:$C$117,MATCH($A8,Stock_Snapshot!$A$2:$A$117,0)) | X8: =V8+W8 | Y8: =IF(G8>0,V8/(G8/Assumptions!$B$11),999) | Z8: =S8+U8 | AA8: =IF(V8<S8,"Below safety stock",IF(X8<=T8,"Reorder now",IF(V8>Z8,"Excess","Healthy"))) | AB8: =V8*E8 | AC8: =MAX(0,V8-Z8)*E8 | AD8: =IF(X8<=T8,ROUNDUP(T8+U8-X8,0),0) | AE8: =MAX(0,T8-X8)*E8 | AF8: =IF(INDEX(Stock_Snapshot!$D$2:$D$117,MATCH($A8,Stock_Snapshot!$A$2:$A$117,0))="","",INDEX(Stock_Snapshot!$D$2:$D$117,MATCH($A8,Stock_Snapshot!$A$2:$A$117,0))) | AG8: =IF(AF8="","",IF(AF8<=EDATE(Assumptions!$B$4,Assumptions!$B$12),"Expires < "&Assumptions!$B$12&" m","OK"))
A9: CMD-0005 | B9: =INDEX(Items!$B$2:$B$117,MATCH($A9,Items!$A$2:$A$117,0)) | C9: =INDEX(Items!$C$2:$C$117,MATCH($A9,Items!$A$2:$A$117,0)) | D9: =INDEX(Items!$D$2:$D$117,MATCH($A9,Items!$A$2:$A$117,0)) | E9: =INDEX(Items!$E$2:$E$117,MATCH($A9,Items!$A$2:$A$117,0)) | F9: =SUM(INDEX(Demand!$N$2:$Y$117,MATCH($A9,Demand!$A$2:$A$117,0),0)) | G9: =F9/12 | H9: =STDEV(INDEX(Demand!$N$2:$Y$117,MATCH($A9,Demand!$A$2:$A$117,0),0)) | I9: =IF(G9>0,H9/G9,0) | J9: =F9*E9 | K9: =SUMIF($J$5:$J$120,">="&J9)/SUM($J$5:$J$120) | L9: =IF(K9<=Assumptions!$B$7,"A",IF(K9<=Assumptions!$B$8,"B","C")) | M9: =IF(I9<=Assumptions!$B$9,"X",IF(I9<=Assumptions!$B$10,"Y","Z")) | N9: =L9&M9 | O9: =INDEX(Assumptions!$F$4:$F$6,MATCH(L9,Assumptions!$E$4:$E$6,0)) | P9: =NORMSINV(O9) | Q9: =IFERROR(AVERAGEIFS(PO_Lines!$R$2:$R$2025,PO_Lines!$B$2:$B$2025,$A9,PO_Lines!$Q$2:$Q$2025,1),INDEX(Items!$F$2:$F$117,MATCH($A9,Items!$A$2:$A$117,0))) | R9: =IFERROR(SQRT(SUMPRODUCT((PO_Lines!$B$2:$B$2025=$A9)*PO_Lines!$Q$2:$Q$2025*(PO_Lines!$R$2:$R$2025-Q9)^2)/(COUNTIFS(PO_Lines!$B$2:$B$2025,$A9,PO_Lines!$Q$2:$Q$2025,1)-1)),0) | S9: =ROUNDUP(P9*SQRT((Q9/Assumptions!$B$11)*H9^2+G9^2*(R9/Assumptions!$B$11)^2),0) | T9: =ROUNDUP(G9*Q9/Assumptions!$B$11+S9,0) | U9: =ROUNDUP(MAX(INDEX(Items!$G$2:$G$117,MATCH($A9,Items!$A$2:$A$117,0)),SQRT(2*F9*Assumptions!$B$5/(Assumptions!$B$6*E9)),G9*Assumptions!$B$16),0) | V9: =INDEX(Stock_Snapshot!$B$2:$B$117,MATCH($A9,Stock_Snapshot!$A$2:$A$117,0)) | W9: =INDEX(Stock_Snapshot!$C$2:$C$117,MATCH($A9,Stock_Snapshot!$A$2:$A$117,0)) | X9: =V9+W9 | Y9: =IF(G9>0,V9/(G9/Assumptions!$B$11),999) | Z9: =S9+U9 | AA9: =IF(V9<S9,"Below safety stock",IF(X9<=T9,"Reorder now",IF(V9>Z9,"Excess","Healthy"))) | AB9: =V9*E9 | AC9: =MAX(0,V9-Z9)*E9 | AD9: =IF(X9<=T9,ROUNDUP(T9+U9-X9,0),0) | AE9: =MAX(0,T9-X9)*E9 | AF9: =IF(INDEX(Stock_Snapshot!$D$2:$D$117,MATCH($A9,Stock_Snapshot!$A$2:$A$117,0))="","",INDEX(Stock_Snapshot!$D$2:$D$117,MATCH($A9,Stock_Snapshot!$A$2:$A$117,0))) | AG9: =IF(AF9="","",IF(AF9<=EDATE(Assumptions!$B$4,Assumptions!$B$12),"Expires < "&Assumptions!$B$12&" m","OK"))
A10: CMD-0006 | B10: =INDEX(Items!$B$2:$B$117,MATCH($A10,Items!$A$2:$A$117,0)) | C10: =INDEX(Items!$C$2:$C$117,MATCH($A10,Items!$A$2:$A$117,0)) | D10: =INDEX(Items!$D$2:$D$117,MATCH($A10,Items!$A$2:$A$117,0)) | E10: =INDEX(Items!$E$2:$E$117,MATCH($A10,Items!$A$2:$A$117,0)) | F10: =SUM(INDEX(Demand!$N$2:$Y$117,MATCH($A10,Demand!$A$2:$A$117,0),0)) | G10: =F10/12 | H10: =STDEV(INDEX(Demand!$N$2:$Y$117,MATCH($A10,Demand!$A$2:$A$117,0),0)) | I10: =IF(G10>0,H10/G10,0) | J10: =F10*E10 | K10: =SUMIF($J$5:$J$120,">="&J10)/SUM($J$5:$J$120) | L10: =IF(K10<=Assumptions!$B$7,"A",IF(K10<=Assumptions!$B$8,"B","C")) | M10: =IF(I10<=Assumptions!$B$9,"X",IF(I10<=Assumptions!$B$10,"Y","Z")) | N10: =L10&M10 | O10: =INDEX(Assumptions!$F$4:$F$6,MATCH(L10,Assumptions!$E$4:$E$6,0)) | P10: =NORMSINV(O10) | Q10: =IFERROR(AVERAGEIFS(PO_Lines!$R$2:$R$2025,PO_Lines!$B$2:$B$2025,$A10,PO_Lines!$Q$2:$Q$2025,1),INDEX(Items!$F$2:$F$117,MATCH($A10,Items!$A$2:$A$117,0))) | R10: =IFERROR(SQRT(SUMPRODUCT((PO_Lines!$B$2:$B$2025=$A10)*PO_Lines!$Q$2:$Q$2025*(PO_Lines!$R$2:$R$2025-Q10)^2)/(COUNTIFS(PO_Lines!$B$2:$B$2025,$A10,PO_Lines!$Q$2:$Q$2025,1)-1)),0) | S10: =ROUNDUP(P10*SQRT((Q10/Assumptions!$B$11)*H10^2+G10^2*(R10/Assumptions!$B$11)^2),0) | T10: =ROUNDUP(G10*Q10/Assumptions!$B$11+S10,0) | U10: =ROUNDUP(MAX(INDEX(Items!$G$2:$G$117,MATCH($A10,Items!$A$2:$A$117,0)),SQRT(2*F10*Assumptions!$B$5/(Assumptions!$B$6*E10)),G10*Assumptions!$B$16),0) | V10: =INDEX(Stock_Snapshot!$B$2:$B$117,MATCH($A10,Stock_Snapshot!$A$2:$A$117,0)) | W10: =INDEX(Stock_Snapshot!$C$2:$C$117,MATCH($A10,Stock_Snapshot!$A$2:$A$117,0)) | X10: =V10+W10 | Y10: =IF(G10>0,V10/(G10/Assumptions!$B$11),999) | Z10: =S10+U10 | AA10: =IF(V10<S10,"Below safety stock",IF(X10<=T10,"Reorder now",IF(V10>Z10,"Excess","Healthy"))) | AB10: =V10*E10 | AC10: =MAX(0,V10-Z10)*E10 | AD10: =IF(X10<=T10,ROUNDUP(T10+U10-X10,0),0) | AE10: =MAX(0,T10-X10)*E10 | AF10: =IF(INDEX(Stock_Snapshot!$D$2:$D$117,MATCH($A10,Stock_Snapshot!$A$2:$A$117,0))="","",INDEX(Stock_Snapshot!$D$2:$D$117,MATCH($A10,Stock_Snapshot!$A$2:$A$117,0))) | AG10: =IF(AF10="","",IF(AF10<=EDATE(Assumptions!$B$4,Assumptions!$B$12),"Expires < "&Assumptions!$B$12&" m","OK"))
A11: CMD-0007 | B11: =INDEX(Items!$B$2:$B$117,MATCH($A11,Items!$A$2:$A$117,0)) | C11: =INDEX(Items!$C$2:$C$117,MATCH($A11,Items!$A$2:$A$117,0)) | D11: =INDEX(Items!$D$2:$D$117,MATCH($A11,Items!$A$2:$A$117,0)) | E11: =INDEX(Items!$E$2:$E$117,MATCH($A11,Items!$A$2:$A$117,0)) | F11: =SUM(INDEX(Demand!$N$2:$Y$117,MATCH($A11,Demand!$A$2:$A$117,0),0)) | G11: =F11/12 | H11: =STDEV(INDEX(Demand!$N$2:$Y$117,MATCH($A11,Demand!$A$2:$A$117,0),0)) | I11: =IF(G11>0,H11/G11,0) | J11: =F11*E11 | K11: =SUMIF($J$5:$J$120,">="&J11)/SUM($J$5:$J$120) | L11: =IF(K11<=Assumptions!$B$7,"A",IF(K11<=Assumptions!$B$8,"B","C")) | M11: =IF(I11<=Assumptions!$B$9,"X",IF(I11<=Assumptions!$B$10,"Y","Z")) | N11: =L11&M11 | O11: =INDEX(Assumptions!$F$4:$F$6,MATCH(L11,Assumptions!$E$4:$E$6,0)) | P11: =NORMSINV(O11) | Q11: =IFERROR(AVERAGEIFS(PO_Lines!$R$2:$R$2025,PO_Lines!$B$2:$B$2025,$A11,PO_Lines!$Q$2:$Q$2025,1),INDEX(Items!$F$2:$F$117,MATCH($A11,Items!$A$2:$A$117,0))) | R11: =IFERROR(SQRT(SUMPRODUCT((PO_Lines!$B$2:$B$2025=$A11)*PO_Lines!$Q$2:$Q$2025*(PO_Lines!$R$2:$R$2025-Q11)^2)/(COUNTIFS(PO_Lines!$B$2:$B$2025,$A11,PO_Lines!$Q$2:$Q$2025,1)-1)),0) | S11: =ROUNDUP(P11*SQRT((Q11/Assumptions!$B$11)*H11^2+G11^2*(R11/Assumptions!$B$11)^2),0) | T11: =ROUNDUP(G11*Q11/Assumptions!$B$11+S11,0) | U11: =ROUNDUP(MAX(INDEX(Items!$G$2:$G$117,MATCH($A11,Items!$A$2:$A$117,0)),SQRT(2*F11*Assumptions!$B$5/(Assumptions!$B$6*E11)),G11*Assumptions!$B$16),0) | V11: =INDEX(Stock_Snapshot!$B$2:$B$117,MATCH($A11,Stock_Snapshot!$A$2:$A$117,0)) | W11: =INDEX(Stock_Snapshot!$C$2:$C$117,MATCH($A11,Stock_Snapshot!$A$2:$A$117,0)) | X11: =V11+W11 | Y11: =IF(G11>0,V11/(G11/Assumptions!$B$11),999) | Z11: =S11+U11 | AA11: =IF(V11<S11,"Below safety stock",IF(X11<=T11,"Reorder now",IF(V11>Z11,"Excess","Healthy"))) | AB11: =V11*E11 | AC11: =MAX(0,V11-Z11)*E11 | AD11: =IF(X11<=T11,ROUNDUP(T11+U11-X11,0),0) | AE11: =MAX(0,T11-X11)*E11 | AF11: =IF(INDEX(Stock_Snapshot!$D$2:$D$117,MATCH($A11,Stock_Snapshot!$A$2:$A$117,0))="","",INDEX(Stock_Snapshot!$D$2:$D$117,MATCH($A11,Stock_Snapshot!$A$2:$A$117,0))) | AG11: =IF(AF11="","",IF(AF11<=EDATE(Assumptions!$B$4,Assumptions!$B$12),"Expires < "&Assumptions!$B$12&" m","OK"))
A12: CMD-0008 | B12: =INDEX(Items!$B$2:$B$117,MATCH($A12,Items!$A$2:$A$117,0)) | C12: =INDEX(Items!$C$2:$C$117,MATCH($A12,Items!$A$2:$A$117,0)) | D12: =INDEX(Items!$D$2:$D$117,MATCH($A12,Items!$A$2:$A$117,0)) | E12: =INDEX(Items!$E$2:$E$117,MATCH($A12,Items!$A$2:$A$117,0)) | F12: =SUM(INDEX(Demand!$N$2:$Y$117,MATCH($A12,Demand!$A$2:$A$117,0),0)) | G12: =F12/12 | H12: =STDEV(INDEX(Demand!$N$2:$Y$117,MATCH($A12,Demand!$A$2:$A$117,0),0)) | I12: =IF(G12>0,H12/G12,0) | J12: =F12*E12 | K12: =SUMIF($J$5:$J$120,">="&J12)/SUM($J$5:$J$120) | L12: =IF(K12<=Assumptions!$B$7,"A",IF(K12<=Assumptions!$B$8,"B","C")) | M12: =IF(I12<=Assumptions!$B$9,"X",IF(I12<=Assumptions!$B$10,"Y","Z")) | N12: =L12&M12 | O12: =INDEX(Assumptions!$F$4:$F$6,MATCH(L12,Assumptions!$E$4:$E$6,0)) | P12: =NORMSINV(O12) | Q12: =IFERROR(AVERAGEIFS(PO_Lines!$R$2:$R$2025,PO_Lines!$B$2:$B$2025,$A12,PO_Lines!$Q$2:$Q$2025,1),INDEX(Items!$F$2:$F$117,MATCH($A12,Items!$A$2:$A$117,0))) | R12: =IFERROR(SQRT(SUMPRODUCT((PO_Lines!$B$2:$B$2025=$A12)*PO_Lines!$Q$2:$Q$2025*(PO_Lines!$R$2:$R$2025-Q12)^2)/(COUNTIFS(PO_Lines!$B$2:$B$2025,$A12,PO_Lines!$Q$2:$Q$2025,1)-1)),0) | S12: =ROUNDUP(P12*SQRT((Q12/Assumptions!$B$11)*H12^2+G12^2*(R12/Assumptions!$B$11)^2),0) | T12: =ROUNDUP(G12*Q12/Assumptions!$B$11+S12,0) | U12: =ROUNDUP(MAX(INDEX(Items!$G$2:$G$117,MATCH($A12,Items!$A$2:$A$117,0)),SQRT(2*F12*Assumptions!$B$5/(Assumptions!$B$6*E12)),G12*Assumptions!$B$16),0) | V12: =INDEX(Stock_Snapshot!$B$2:$B$117,MATCH($A12,Stock_Snapshot!$A$2:$A$117,0)) | W12: =INDEX(Stock_Snapshot!$C$2:$C$117,MATCH($A12,Stock_Snapshot!$A$2:$A$117,0)) | X12: =V12+W12 | Y12: =IF(G12>0,V12/(G12/Assumptions!$B$11),999) | Z12: =S12+U12 | AA12: =IF(V12<S12,"Below safety stock",IF(X12<=T12,"Reorder now",IF(V12>Z12,"Excess","Healthy"))) | AB12: =V12*E12 | AC12: =MAX(0,V12-Z12)*E12 | AD12: =IF(X12<=T12,ROUNDUP(T12+U12-X12,0),0) | AE12: =MAX(0,T12-X12)*E12 | AF12: =IF(INDEX(Stock_Snapshot!$D$2:$D$117,MATCH($A12,Stock_Snapshot!$A$2:$A$117,0))="","",INDEX(Stock_Snapshot!$D$2:$D$117,MATCH($A12,Stock_Snapshot!$A$2:$A$117,0))) | AG12: =IF(AF12="","",IF(AF12<=EDATE(Assumptions!$B$4,Assumptions!$B$12),"Expires < "&Assumptions!$B$12&" m","OK"))
A13: CMD-0009 | B13: =INDEX(Items!$B$2:$B$117,MATCH($A13,Items!$A$2:$A$117,0)) | C13: =INDEX(Items!$C$2:$C$117,MATCH($A13,Items!$A$2:$A$117,0)) | D13: =INDEX(Items!$D$2:$D$117,MATCH($A13,Items!$A$2:$A$117,0)) | E13: =INDEX(Items!$E$2:$E$117,MATCH($A13,Items!$A$2:$A$117,0)) | F13: =SUM(INDEX(Demand!$N$2:$Y$117,MATCH($A13,Demand!$A$2:$A$117,0),0)) | G13: =F13/12 | H13: =STDEV(INDEX(Demand!$N$2:$Y$117,MATCH($A13,Demand!$A$2:$A$117,0),0)) | I13: =IF(G13>0,H13/G13,0) | J13: =F13*E13 | K13: =SUMIF($J$5:$J$120,">="&J13)/SUM($J$5:$J$120) | L13: =IF(K13<=Assumptions!$B$7,"A",IF(K13<=Assumptions!$B$8,"B","C")) | M13: =IF(I13<=Assumptions!$B$9,"X",IF(I13<=Assumptions!$B$10,"Y","Z")) | N13: =L13&M13 | O13: =INDEX(Assumptions!$F$4:$F$6,MATCH(L13,Assumptions!$E$4:$E$6,0)) | P13: =NORMSINV(O13) | Q13: =IFERROR(AVERAGEIFS(PO_Lines!$R$2:$R$2025,PO_Lines!$B$2:$B$2025,$A13,PO_Lines!$Q$2:$Q$2025,1),INDEX(Items!$F$2:$F$117,MATCH($A13,Items!$A$2:$A$117,0))) | R13: =IFERROR(SQRT(SUMPRODUCT((PO_Lines!$B$2:$B$2025=$A13)*PO_Lines!$Q$2:$Q$2025*(PO_Lines!$R$2:$R$2025-Q13)^2)/(COUNTIFS(PO_Lines!$B$2:$B$2025,$A13,PO_Lines!$Q$2:$Q$2025,1)-1)),0) | S13: =ROUNDUP(P13*SQRT((Q13/Assumptions!$B$11)*H13^2+G13^2*(R13/Assumptions!$B$11)^2),0) | T13: =ROUNDUP(G13*Q13/Assumptions!$B$11+S13,0) | U13: =ROUNDUP(MAX(INDEX(Items!$G$2:$G$117,MATCH($A13,Items!$A$2:$A$117,0)),SQRT(2*F13*Assumptions!$B$5/(Assumptions!$B$6*E13)),G13*Assumptions!$B$16),0) | V13: =INDEX(Stock_Snapshot!$B$2:$B$117,MATCH($A13,Stock_Snapshot!$A$2:$A$117,0)) | W13: =INDEX(Stock_Snapshot!$C$2:$C$117,MATCH($A13,Stock_Snapshot!$A$2:$A$117,0)) | X13: =V13+W13 | Y13: =IF(G13>0,V13/(G13/Assumptions!$B$11),999) | Z13: =S13+U13 | AA13: =IF(V13<S13,"Below safety stock",IF(X13<=T13,"Reorder now",IF(V13>Z13,"Excess","Healthy"))) | AB13: =V13*E13 | AC13: =MAX(0,V13-Z13)*E13 | AD13: =IF(X13<=T13,ROUNDUP(T13+U13-X13,0),0) | AE13: =MAX(0,T13-X13)*E13 | AF13: =IF(INDEX(Stock_Snapshot!$D$2:$D$117,MATCH($A13,Stock_Snapshot!$A$2:$A$117,0))="","",INDEX(Stock_Snapshot!$D$2:$D$117,MATCH($A13,Stock_Snapshot!$A$2:$A$117,0))) | AG13: =IF(AF13="","",IF(AF13<=EDATE(Assumptions!$B$4,Assumptions!$B$12),"Expires < "&Assumptions!$B$12&" m","OK"))
A14: CMD-0010 | B14: =INDEX(Items!$B$2:$B$117,MATCH($A14,Items!$A$2:$A$117,0)) | C14: =INDEX(Items!$C$2:$C$117,MATCH($A14,Items!$A$2:$A$117,0)) | D14: =INDEX(Items!$D$2:$D$117,MATCH($A14,Items!$A$2:$A$117,0)) | E14: =INDEX(Items!$E$2:$E$117,MATCH($A14,Items!$A$2:$A$117,0)) | F14: =SUM(INDEX(Demand!$N$2:$Y$117,MATCH($A14,Demand!$A$2:$A$117,0),0)) | G14: =F14/12 | H14: =STDEV(INDEX(Demand!$N$2:$Y$117,MATCH($A14,Demand!$A$2:$A$117,0),0)) | I14: =IF(G14>0,H14/G14,0) | J14: =F14*E14 | K14: =SUMIF($J$5:$J$120,">="&J14)/SUM($J$5:$J$120) | L14: =IF(K14<=Assumptions!$B$7,"A",IF(K14<=Assumptions!$B$8,"B","C")) | M14: =IF(I14<=Assumptions!$B$9,"X",IF(I14<=Assumptions!$B$10,"Y","Z")) | N14: =L14&M14 | O14: =INDEX(Assumptions!$F$4:$F$6,MATCH(L14,Assumptions!$E$4:$E$6,0)) | P14: =NORMSINV(O14) | Q14: =IFERROR(AVERAGEIFS(PO_Lines!$R$2:$R$2025,PO_Lines!$B$2:$B$2025,$A14,PO_Lines!$Q$2:$Q$2025,1),INDEX(Items!$F$2:$F$117,MATCH($A14,Items!$A$2:$A$117,0))) | R14: =IFERROR(SQRT(SUMPRODUCT((PO_Lines!$B$2:$B$2025=$A14)*PO_Lines!$Q$2:$Q$2025*(PO_Lines!$R$2:$R$2025-Q14)^2)/(COUNTIFS(PO_Lines!$B$2:$B$2025,$A14,PO_Lines!$Q$2:$Q$2025,1)-1)),0) | S14: =ROUNDUP(P14*SQRT((Q14/Assumptions!$B$11)*H14^2+G14^2*(R14/Assumptions!$B$11)^2),0) | T14: =ROUNDUP(G14*Q14/Assumptions!$B$11+S14,0) | U14: =ROUNDUP(MAX(INDEX(Items!$G$2:$G$117,MATCH($A14,Items!$A$2:$A$117,0)),SQRT(2*F14*Assumptions!$B$5/(Assumptions!$B$6*E14)),G14*Assumptions!$B$16),0) | V14: =INDEX(Stock_Snapshot!$B$2:$B$117,MATCH($A14,Stock_Snapshot!$A$2:$A$117,0)) | W14: =INDEX(Stock_Snapshot!$C$2:$C$117,MATCH($A14,Stock_Snapshot!$A$2:$A$117,0)) | X14: =V14+W14 | Y14: =IF(G14>0,V14/(G14/Assumptions!$B$11),999) | Z14: =S14+U14 | AA14: =IF(V14<S14,"Below safety stock",IF(X14<=T14,"Reorder now",IF(V14>Z14,"Excess","Healthy"))) | AB14: =V14*E14 | AC14: =MAX(0,V14-Z14)*E14 | AD14: =IF(X14<=T14,ROUNDUP(T14+U14-X14,0),0) | AE14: =MAX(0,T14-X14)*E14 | AF14: =IF(INDEX(Stock_Snapshot!$D$2:$D$117,MATCH($A14,Stock_Snapshot!$A$2:$A$117,0))="","",INDEX(Stock_Snapshot!$D$2:$D$117,MATCH($A14,Stock_Snapshot!$A$2:$A$117,0))) | AG14: =IF(AF14="","",IF(AF14<=EDATE(Assumptions!$B$4,Assumptions!$B$12),"Expires < "&Assumptions!$B$12&" m","OK"))
A15: CMD-0011 | B15: =INDEX(Items!$B$2:$B$117,MATCH($A15,Items!$A$2:$A$117,0)) | C15: =INDEX(Items!$C$2:$C$117,MATCH($A15,Items!$A$2:$A$117,0)) | D15: =INDEX(Items!$D$2:$D$117,MATCH($A15,Items!$A$2:$A$117,0)) | E15: =INDEX(Items!$E$2:$E$117,MATCH($A15,Items!$A$2:$A$117,0)) | F15: =SUM(INDEX(Demand!$N$2:$Y$117,MATCH($A15,Demand!$A$2:$A$117,0),0)) | G15: =F15/12 | H15: =STDEV(INDEX(Demand!$N$2:$Y$117,MATCH($A15,Demand!$A$2:$A$117,0),0)) | I15: =IF(G15>0,H15/G15,0) | J15: =F15*E15 | K15: =SUMIF($J$5:$J$120,">="&J15)/SUM($J$5:$J$120) | L15: =IF(K15<=Assumptions!$B$7,"A",IF(K15<=Assumptions!$B$8,"B","C")) | M15: =IF(I15<=Assumptions!$B$9,"X",IF(I15<=Assumptions!$B$10,"Y","Z")) | N15: =L15&M15 | O15: =INDEX(Assumptions!$F$4:$F$6,MATCH(L15,Assumptions!$E$4:$E$6,0)) | P15: =NORMSINV(O15) | Q15: =IFERROR(AVERAGEIFS(PO_Lines!$R$2:$R$2025,PO_Lines!$B$2:$B$2025,$A15,PO_Lines!$Q$2:$Q$2025,1),INDEX(Items!$F$2:$F$117,MATCH($A15,Items!$A$2:$A$117,0))) | R15: =IFERROR(SQRT(SUMPRODUCT((PO_Lines!$B$2:$B$2025=$A15)*PO_Lines!$Q$2:$Q$2025*(PO_Lines!$R$2:$R$2025-Q15)^2)/(COUNTIFS(PO_Lines!$B$2:$B$2025,$A15,PO_Lines!$Q$2:$Q$2025,1)-1)),0) | S15: =ROUNDUP(P15*SQRT((Q15/Assumptions!$B$11)*H15^2+G15^2*(R15/Assumptions!$B$11)^2),0) | T15: =ROUNDUP(G15*Q15/Assumptions!$B$11+S15,0) | U15: =ROUNDUP(MAX(INDEX(Items!$G$2:$G$117,MATCH($A15,Items!$A$2:$A$117,0)),SQRT(2*F15*Assumptions!$B$5/(Assumptions!$B$6*E15)),G15*Assumptions!$B$16),0) | V15: =INDEX(Stock_Snapshot!$B$2:$B$117,MATCH($A15,Stock_Snapshot!$A$2:$A$117,0)) | W15: =INDEX(Stock_Snapshot!$C$2:$C$117,MATCH($A15,Stock_Snapshot!$A$2:$A$117,0)) | X15: =V15+W15 | Y15: =IF(G15>0,V15/(G15/Assumptions!$B$11),999) | Z15: =S15+U15 | AA15: =IF(V15<S15,"Below safety stock",IF(X15<=T15,"Reorder now",IF(V15>Z15,"Excess","Healthy"))) | AB15: =V15*E15 | AC15: =MAX(0,V15-Z15)*E15 | AD15: =IF(X15<=T15,ROUNDUP(T15+U15-X15,0),0) | AE15: =MAX(0,T15-X15)*E15 | AF15: =IF(INDEX(Stock_Snapshot!$D$2:$D$117,MATCH($A15,Stock_Snapshot!$A$2:$A$117,0))="","",INDEX(Stock_Snapshot!$D$2:$D$117,MATCH($A15,Stock_Snapshot!$A$2:$A$117,0))) | AG15: =IF(AF15="","",IF(AF15<=EDATE(Assumptions!$B$4,Assumptions!$B$12),"Expires < "&Assumptions!$B$12&" m","OK"))
A16: CMD-0012 | B16: =INDEX(Items!$B$2:$B$117,MATCH($A16,Items!$A$2:$A$117,0)) | C16: =INDEX(Items!$C$2:$C$117,MATCH($A16,Items!$A$2:$A$117,0)) | D16: =INDEX(Items!$D$2:$D$117,MATCH($A16,Items!$A$2:$A$117,0)) | E16: =INDEX(Items!$E$2:$E$117,MATCH($A16,Items!$A$2:$A$117,0)) | F16: =SUM(INDEX(Demand!$N$2:$Y$117,MATCH($A16,Demand!$A$2:$A$117,0),0)) | G16: =F16/12 | H16: =STDEV(INDEX(Demand!$N$2:$Y$117,MATCH($A16,Demand!$A$2:$A$117,0),0)) | I16: =IF(G16>0,H16/G16,0) | J16: =F16*E16 | K16: =SUMIF($J$5:$J$120,">="&J16)/SUM($J$5:$J$120) | L16: =IF(K16<=Assumptions!$B$7,"A",IF(K16<=Assumptions!$B$8,"B","C")) | M16: =IF(I16<=Assumptions!$B$9,"X",IF(I16<=Assumptions!$B$10,"Y","Z")) | N16: =L16&M16 | O16: =INDEX(Assumptions!$F$4:$F$6,MATCH(L16,Assumptions!$E$4:$E$6,0)) | P16: =NORMSINV(O16) | Q16: =IFERROR(AVERAGEIFS(PO_Lines!$R$2:$R$2025,PO_Lines!$B$2:$B$2025,$A16,PO_Lines!$Q$2:$Q$2025,1),INDEX(Items!$F$2:$F$117,MATCH($A16,Items!$A$2:$A$117,0))) | R16: =IFERROR(SQRT(SUMPRODUCT((PO_Lines!$B$2:$B$2025=$A16)*PO_Lines!$Q$2:$Q$2025*(PO_Lines!$R$2:$R$2025-Q16)^2)/(COUNTIFS(PO_Lines!$B$2:$B$2025,$A16,PO_Lines!$Q$2:$Q$2025,1)-1)),0) | S16: =ROUNDUP(P16*SQRT((Q16/Assumptions!$B$11)*H16^2+G16^2*(R16/Assumptions!$B$11)^2),0) | T16: =ROUNDUP(G16*Q16/Assumptions!$B$11+S16,0) | U16: =ROUNDUP(MAX(INDEX(Items!$G$2:$G$117,MATCH($A16,Items!$A$2:$A$117,0)),SQRT(2*F16*Assumptions!$B$5/(Assumptions!$B$6*E16)),G16*Assumptions!$B$16),0) | V16: =INDEX(Stock_Snapshot!$B$2:$B$117,MATCH($A16,Stock_Snapshot!$A$2:$A$117,0)) | W16: =INDEX(Stock_Snapshot!$C$2:$C$117,MATCH($A16,Stock_Snapshot!$A$2:$A$117,0)) | X16: =V16+W16 | Y16: =IF(G16>0,V16/(G16/Assumptions!$B$11),999) | Z16: =S16+U16 | AA16: =IF(V16<S16,"Below safety stock",IF(X16<=T16,"Reorder now",IF(V16>Z16,"Excess","Healthy"))) | AB16: =V16*E16 | AC16: =MAX(0,V16-Z16)*E16 | AD16: =IF(X16<=T16,ROUNDUP(T16+U16-X16,0),0) | AE16: =MAX(0,T16-X16)*E16 | AF16: =IF(INDEX(Stock_Snapshot!$D$2:$D$117,MATCH($A16,Stock_Snapshot!$A$2:$A$117,0))="","",INDEX(Stock_Snapshot!$D$2:$D$117,MATCH($A16,Stock_Snapshot!$A$2:$A$117,0))) | AG16: =IF(AF16="","",IF(AF16<=EDATE(Assumptions!$B$4,Assumptions!$B$12),"Expires < "&Assumptions!$B$12&" m","OK"))
... A120: CMD-0116 | B120: =INDEX(Items!$B$2:$B$117,MATCH($A120,Items!$A$2:$A$117,0)) | C120: =INDEX(Items!$C$2:$C$117,MATCH($A120,Items!$A$2:$A$117,0)) | D120: =INDEX(Items!$D$2:$D$117,MATCH($A120,Items!$A$2:$A$117,0)) | E120: =INDEX(Items!$E$2:$E$117,MATCH($A120,Items!$A$2:$A$117,0)) | F120: =SUM(INDEX(Demand!$N$2:$Y$117,MATCH($A120,Demand!$A$2:$A$117,0),0)) | G120: =F120/12 | H120: =STDEV(INDEX(Demand!$N$2:$Y$117,MATCH($A120,Demand!$A$2:$A$117,0),0)) | I120: =IF(G120>0,H120/G120,0) | J120: =F120*E120 | K120: =SUMIF($J$5:$J$120,">="&J120)/SUM($J$5:$J$120) | L120: =IF(K120<=Assumptions!$B$7,"A",IF(K120<=Assumptions!$B$8,"B","C")) | M120: =IF(I120<=Assumptions!$B$9,"X",IF(I120<=Assumptions!$B$10,"Y","Z")) | N120: =L120&M120 | O120: =INDEX(Assumptions!$F$4:$F$6,MATCH(L120,Assumptions!$E$4:$E$6,0)) | P120: =NORMSINV(O120) | Q120: =IFERROR(AVERAGEIFS(PO_Lines!$R$2:$R$2025,PO_Lines!$B$2:$B$2025,$A120,PO_Lines!$Q$2:$Q$2025,1),INDEX(Items!$F$2:$F$117,MATCH($A120,Items!$A$2:$A$117,0))) | R120: =IFERROR(SQRT(SUMPRODUCT((PO_Lines!$B$2:$B$2025=$A120)*PO_Lines!$Q$2:$Q$2025*(PO_Lines!$R$2:$R$2025-Q120)^2)/(COUNTIFS(PO_Lines!$B$2:$B$2025,$A120,PO_Lines!$Q$2:$Q$2025,1)-1)),0) | S120: =ROUNDUP(P120*SQRT((Q120/Assumptions!$B$11)*H120^2+G120^2*(R120/Assumptions!$B$11)^2),0) | T120: =ROUNDUP(G120*Q120/Assumptions!$B$11+S120,0) | U120: =ROUNDUP(MAX(INDEX(Items!$G$2:$G$117,MATCH($A120,Items!$A$2:$A$117,0)),SQRT(2*F120*Assumptions!$B$5/(Assumptions!$B$6*E120)),G120*Assumptions!$B$16),0) | V120: =INDEX(Stock_Snapshot!$B$2:$B$117,MATCH($A120,Stock_Snapshot!$A$2:$A$117,0)) | W120: =INDEX(Stock_Snapshot!$C$2:$C$117,MATCH($A120,Stock_Snapshot!$A$2:$A$117,0)) | X120: =V120+W120 | Y120: =IF(G120>0,V120/(G120/Assumptions!$B$11),999) | Z120: =S120+U120 | AA120: =IF(V120<S120,"Below safety stock",IF(X120<=T120,"Reorder now",IF(V120>Z120,"Excess","Healthy"))) | AB120: =V120*E120 | AC120: =MAX(0,V120-Z120)*E120 | AD120: =IF(X120<=T120,ROUNDUP(T120+U120-X120,0),0) | AE120: =MAX(0,T120-X120)*E120 | AF120: =IF(INDEX(Stock_Snapshot!$D$2:$D$117,MATCH($A120,Stock_Snapshot!$A$2:$A$117,0))="","",INDEX(Stock_Snapshot!$D$2:$D$117,MATCH($A120,Stock_Snapshot!$A$2:$A$117,0))) | AG120: =IF(AF120="","",IF(AF120<=EDATE(Assumptions!$B$4,Assumptions!$B$12),"Expires < "&Assumptions!$B$12&" m","OK"))

Sheet Supplier_Scorecard
A1: Supplier Scorecard
A2: On-time, in-full (OTIF), quality and lead-time performance per supplier, all POs received Oct-2024 to Sep-2026.
A4: Supplier ID | B4: Supplier | C4: Country | D4: SKUs supplied | E4: Single-source SKUs | F4: POs received | G4: FY spend (€) | H4: On-time % | I4: In-full % | J4: OTIF % | K4: Avg days late (late POs) | L4: Reject rate | M4: Avg actual lead time (days) | N4: Rating
A5: S01 | B5: Shannon Electronics Ltd | C5: Ireland | D5: =COUNTIF(Items!$D$2:$D$117,A5) | E5: =COUNTIFS(Items!$D$2:$D$117,A5,Items!$I$2:$I$117,TRUE) | F5: =COUNTIFS(PO_Lines!$C$2:$C$2025,A5,PO_Lines!$Q$2:$Q$2025,1) | G5: =SUMIFS(PO_Lines!$O$2:$O$2025,PO_Lines!$C$2:$C$2025,A5,PO_Lines!$D$2:$D$2025,">="&Assumptions!$B$13) | H5: =IFERROR(SUMIFS(PO_Lines!$S$2:$S$2025,PO_Lines!$C$2:$C$2025,A5)/F5,0) | I5: =IFERROR(SUMIFS(PO_Lines!$T$2:$T$2025,PO_Lines!$C$2:$C$2025,A5)/F5,0) | J5: =IFERROR(SUMIFS(PO_Lines!$U$2:$U$2025,PO_Lines!$C$2:$C$2025,A5)/F5,0) | K5: =IFERROR(AVERAGEIFS(PO_Lines!$V$2:$V$2025,PO_Lines!$C$2:$C$2025,A5,PO_Lines!$V$2:$V$2025,">0"),0) | L5: =IFERROR(SUMIFS(PO_Lines!$I$2:$I$2025,PO_Lines!$C$2:$C$2025,A5)/SUMIFS(PO_Lines!$H$2:$H$2025,PO_Lines!$C$2:$C$2025,A5),0) | M5: =IFERROR(AVERAGEIFS(PO_Lines!$R$2:$R$2025,PO_Lines!$C$2:$C$2025,A5,PO_Lines!$Q$2:$Q$2025,1),0) | N5: =IF(J5>=Assumptions!$B$14,"Preferred",IF(J5>=Assumptions!$B$15,"Approved","Improvement plan"))
A6: S02 | B6: Rhein Sensorik GmbH | C6: Germany | D6: =COUNTIF(Items!$D$2:$D$117,A6) | E6: =COUNTIFS(Items!$D$2:$D$117,A6,Items!$I$2:$I$117,TRUE) | F6: =COUNTIFS(PO_Lines!$C$2:$C$2025,A6,PO_Lines!$Q$2:$Q$2025,1) | G6: =SUMIFS(PO_Lines!$O$2:$O$2025,PO_Lines!$C$2:$C$2025,A6,PO_Lines!$D$2:$D$2025,">="&Assumptions!$B$13) | H6: =IFERROR(SUMIFS(PO_Lines!$S$2:$S$2025,PO_Lines!$C$2:$C$2025,A6)/F6,0) | I6: =IFERROR(SUMIFS(PO_Lines!$T$2:$T$2025,PO_Lines!$C$2:$C$2025,A6)/F6,0) | J6: =IFERROR(SUMIFS(PO_Lines!$U$2:$U$2025,PO_Lines!$C$2:$C$2025,A6)/F6,0) | K6: =IFERROR(AVERAGEIFS(PO_Lines!$V$2:$V$2025,PO_Lines!$C$2:$C$2025,A6,PO_Lines!$V$2:$V$2025,">0"),0) | L6: =IFERROR(SUMIFS(PO_Lines!$I$2:$I$2025,PO_Lines!$C$2:$C$2025,A6)/SUMIFS(PO_Lines!$H$2:$H$2025,PO_Lines!$C$2:$C$2025,A6),0) | M6: =IFERROR(AVERAGEIFS(PO_Lines!$R$2:$R$2025,PO_Lines!$C$2:$C$2025,A6,PO_Lines!$Q$2:$Q$2025,1),0) | N6: =IF(J6>=Assumptions!$B$14,"Preferred",IF(J6>=Assumptions!$B$15,"Approved","Improvement plan"))
A7: S03 | B7: Formosa Microtech Co. | C7: Taiwan | D7: =COUNTIF(Items!$D$2:$D$117,A7) | E7: =COUNTIFS(Items!$D$2:$D$117,A7,Items!$I$2:$I$117,TRUE) | F7: =COUNTIFS(PO_Lines!$C$2:$C$2025,A7,PO_Lines!$Q$2:$Q$2025,1) | G7: =SUMIFS(PO_Lines!$O$2:$O$2025,PO_Lines!$C$2:$C$2025,A7,PO_Lines!$D$2:$D$2025,">="&Assumptions!$B$13) | H7: =IFERROR(SUMIFS(PO_Lines!$S$2:$S$2025,PO_Lines!$C$2:$C$2025,A7)/F7,0) | I7: =IFERROR(SUMIFS(PO_Lines!$T$2:$T$2025,PO_Lines!$C$2:$C$2025,A7)/F7,0) | J7: =IFERROR(SUMIFS(PO_Lines!$U$2:$U$2025,PO_Lines!$C$2:$C$2025,A7)/F7,0) | K7: =IFERROR(AVERAGEIFS(PO_Lines!$V$2:$V$2025,PO_Lines!$C$2:$C$2025,A7,PO_Lines!$V$2:$V$2025,">0"),0) | L7: =IFERROR(SUMIFS(PO_Lines!$I$2:$I$2025,PO_Lines!$C$2:$C$2025,A7)/SUMIFS(PO_Lines!$H$2:$H$2025,PO_Lines!$C$2:$C$2025,A7),0) | M7: =IFERROR(AVERAGEIFS(PO_Lines!$R$2:$R$2025,PO_Lines!$C$2:$C$2025,A7,PO_Lines!$Q$2:$Q$2025,1),0) | N7: =IF(J7>=Assumptions!$B$14,"Preferred",IF(J7>=Assumptions!$B$15,"Approved","Improvement plan"))
A8: S04 | B8: Penang Precision Sdn Bhd | C8: Malaysia | D8: =COUNTIF(Items!$D$2:$D$117,A8) | E8: =COUNTIFS(Items!$D$2:$D$117,A8,Items!$I$2:$I$117,TRUE) | F8: =COUNTIFS(PO_Lines!$C$2:$C$2025,A8,PO_Lines!$Q$2:$Q$2025,1) | G8: =SUMIFS(PO_Lines!$O$2:$O$2025,PO_Lines!$C$2:$C$2025,A8,PO_Lines!$D$2:$D$2025,">="&Assumptions!$B$13) | H8: =IFERROR(SUMIFS(PO_Lines!$S$2:$S$2025,PO_Lines!$C$2:$C$2025,A8)/F8,0) | I8: =IFERROR(SUMIFS(PO_Lines!$T$2:$T$2025,PO_Lines!$C$2:$C$2025,A8)/F8,0) | J8: =IFERROR(SUMIFS(PO_Lines!$U$2:$U$2025,PO_Lines!$C$2:$C$2025,A8)/F8,0) | K8: =IFERROR(AVERAGEIFS(PO_Lines!$V$2:$V$2025,PO_Lines!$C$2:$C$2025,A8,PO_Lines!$V$2:$V$2025,">0"),0) | L8: =IFERROR(SUMIFS(PO_Lines!$I$2:$I$2025,PO_Lines!$C$2:$C$2025,A8)/SUMIFS(PO_Lines!$H$2:$H$2025,PO_Lines!$C$2:$C$2025,A8),0) | M8: =IFERROR(AVERAGEIFS(PO_Lines!$R$2:$R$2025,PO_Lines!$C$2:$C$2025,A8,PO_Lines!$Q$2:$Q$2025,1),0) | N8: =IF(J8>=Assumptions!$B$14,"Preferred",IF(J8>=Assumptions!$B$15,"Approved","Improvement plan"))
A9: S05 | B9: Shenzhen Brightcell Power | C9: China | D9: =COUNTIF(Items!$D$2:$D$117,A9) | E9: =COUNTIFS(Items!$D$2:$D$117,A9,Items!$I$2:$I$117,TRUE) | F9: =COUNTIFS(PO_Lines!$C$2:$C$2025,A9,PO_Lines!$Q$2:$Q$2025,1) | G9: =SUMIFS(PO_Lines!$O$2:$O$2025,PO_Lines!$C$2:$C$2025,A9,PO_Lines!$D$2:$D$2025,">="&Assumptions!$B$13) | H9: =IFERROR(SUMIFS(PO_Lines!$S$2:$S$2025,PO_Lines!$C$2:$C$2025,A9)/F9,0) | I9: =IFERROR(SUMIFS(PO_Lines!$T$2:$T$2025,PO_Lines!$C$2:$C$2025,A9)/F9,0) | J9: =IFERROR(SUMIFS(PO_Lines!$U$2:$U$2025,PO_Lines!$C$2:$C$2025,A9)/F9,0) | K9: =IFERROR(AVERAGEIFS(PO_Lines!$V$2:$V$2025,PO_Lines!$C$2:$C$2025,A9,PO_Lines!$V$2:$V$2025,">0"),0) | L9: =IFERROR(SUMIFS(PO_Lines!$I$2:$I$2025,PO_Lines!$C$2:$C$2025,A9)/SUMIFS(PO_Lines!$H$2:$H$2025,PO_Lines!$C$2:$C$2025,A9),0) | M9: =IFERROR(AVERAGEIFS(PO_Lines!$R$2:$R$2025,PO_Lines!$C$2:$C$2025,A9,PO_Lines!$Q$2:$Q$2025,1),0) | N9: =IF(J9>=Assumptions!$B$14,"Preferred",IF(J9>=Assumptions!$B$15,"Approved","Improvement plan"))
A10: S06 | B10: Midlands Connect UK | C10: United Kingdom | D10: =COUNTIF(Items!$D$2:$D$117,A10) | E10: =COUNTIFS(Items!$D$2:$D$117,A10,Items!$I$2:$I$117,TRUE) | F10: =COUNTIFS(PO_Lines!$C$2:$C$2025,A10,PO_Lines!$Q$2:$Q$2025,1) | G10: =SUMIFS(PO_Lines!$O$2:$O$2025,PO_Lines!$C$2:$C$2025,A10,PO_Lines!$D$2:$D$2025,">="&Assumptions!$B$13) | H10: =IFERROR(SUMIFS(PO_Lines!$S$2:$S$2025,PO_Lines!$C$2:$C$2025,A10)/F10,0) | I10: =IFERROR(SUMIFS(PO_Lines!$T$2:$T$2025,PO_Lines!$C$2:$C$2025,A10)/F10,0) | J10: =IFERROR(SUMIFS(PO_Lines!$U$2:$U$2025,PO_Lines!$C$2:$C$2025,A10)/F10,0) | K10: =IFERROR(AVERAGEIFS(PO_Lines!$V$2:$V$2025,PO_Lines!$C$2:$C$2025,A10,PO_Lines!$V$2:$V$2025,">0"),0) | L10: =IFERROR(SUMIFS(PO_Lines!$I$2:$I$2025,PO_Lines!$C$2:$C$2025,A10)/SUMIFS(PO_Lines!$H$2:$H$2025,PO_Lines!$C$2:$C$2025,A10),0) | M10: =IFERROR(AVERAGEIFS(PO_Lines!$R$2:$R$2025,PO_Lines!$C$2:$C$2025,A10,PO_Lines!$Q$2:$Q$2025,1),0) | N10: =IF(J10>=Assumptions!$B$14,"Preferred",IF(J10>=Assumptions!$B$15,"Approved","Improvement plan"))
A11: S07 | B11: Lakeview Circuits Inc. | C11: USA | D11: =COUNTIF(Items!$D$2:$D$117,A11) | E11: =COUNTIFS(Items!$D$2:$D$117,A11,Items!$I$2:$I$117,TRUE) | F11: =COUNTIFS(PO_Lines!$C$2:$C$2025,A11,PO_Lines!$Q$2:$Q$2025,1) | G11: =SUMIFS(PO_Lines!$O$2:$O$2025,PO_Lines!$C$2:$C$2025,A11,PO_Lines!$D$2:$D$2025,">="&Assumptions!$B$13) | H11: =IFERROR(SUMIFS(PO_Lines!$S$2:$S$2025,PO_Lines!$C$2:$C$2025,A11)/F11,0) | I11: =IFERROR(SUMIFS(PO_Lines!$T$2:$T$2025,PO_Lines!$C$2:$C$2025,A11)/F11,0) | J11: =IFERROR(SUMIFS(PO_Lines!$U$2:$U$2025,PO_Lines!$C$2:$C$2025,A11)/F11,0) | K11: =IFERROR(AVERAGEIFS(PO_Lines!$V$2:$V$2025,PO_Lines!$C$2:$C$2025,A11,PO_Lines!$V$2:$V$2025,">0"),0) | L11: =IFERROR(SUMIFS(PO_Lines!$I$2:$I$2025,PO_Lines!$C$2:$C$2025,A11)/SUMIFS(PO_Lines!$H$2:$H$2025,PO_Lines!$C$2:$C$2025,A11),0) | M11: =IFERROR(AVERAGEIFS(PO_Lines!$R$2:$R$2025,PO_Lines!$C$2:$C$2025,A11,PO_Lines!$Q$2:$Q$2025,1),0) | N11: =IF(J11>=Assumptions!$B$14,"Preferred",IF(J11>=Assumptions!$B$15,"Approved","Improvement plan"))
A12: S08 | B12: Bavaria Display AG | C12: Germany | D12: =COUNTIF(Items!$D$2:$D$117,A12) | E12: =COUNTIFS(Items!$D$2:$D$117,A12,Items!$I$2:$I$117,TRUE) | F12: =COUNTIFS(PO_Lines!$C$2:$C$2025,A12,PO_Lines!$Q$2:$Q$2025,1) | G12: =SUMIFS(PO_Lines!$O$2:$O$2025,PO_Lines!$C$2:$C$2025,A12,PO_Lines!$D$2:$D$2025,">="&Assumptions!$B$13) | H12: =IFERROR(SUMIFS(PO_Lines!$S$2:$S$2025,PO_Lines!$C$2:$C$2025,A12)/F12,0) | I12: =IFERROR(SUMIFS(PO_Lines!$T$2:$T$2025,PO_Lines!$C$2:$C$2025,A12)/F12,0) | J12: =IFERROR(SUMIFS(PO_Lines!$U$2:$U$2025,PO_Lines!$C$2:$C$2025,A12)/F12,0) | K12: =IFERROR(AVERAGEIFS(PO_Lines!$V$2:$V$2025,PO_Lines!$C$2:$C$2025,A12,PO_Lines!$V$2:$V$2025,">0"),0) | L12: =IFERROR(SUMIFS(PO_Lines!$I$2:$I$2025,PO_Lines!$C$2:$C$2025,A12)/SUMIFS(PO_Lines!$H$2:$H$2025,PO_Lines!$C$2:$C$2025,A12),0) | M12: =IFERROR(AVERAGEIFS(PO_Lines!$R$2:$R$2025,PO_Lines!$C$2:$C$2025,A12,PO_Lines!$Q$2:$Q$2025,1),0) | N12: =IF(J12>=Assumptions!$B$14,"Preferred",IF(J12>=Assumptions!$B$15,"Approved","Improvement plan"))
A13: S09 | B13: Atlantic Polymers Ltd | C13: Ireland | D13: =COUNTIF(Items!$D$2:$D$117,A13) | E13: =COUNTIFS(Items!$D$2:$D$117,A13,Items!$I$2:$I$117,TRUE) | F13: =COUNTIFS(PO_Lines!$C$2:$C$2025,A13,PO_Lines!$Q$2:$Q$2025,1) | G13: =SUMIFS(PO_Lines!$O$2:$O$2025,PO_Lines!$C$2:$C$2025,A13,PO_Lines!$D$2:$D$2025,">="&Assumptions!$B$13) | H13: =IFERROR(SUMIFS(PO_Lines!$S$2:$S$2025,PO_Lines!$C$2:$C$2025,A13)/F13,0) | I13: =IFERROR(SUMIFS(PO_Lines!$T$2:$T$2025,PO_Lines!$C$2:$C$2025,A13)/F13,0) | J13: =IFERROR(SUMIFS(PO_Lines!$U$2:$U$2025,PO_Lines!$C$2:$C$2025,A13)/F13,0) | K13: =IFERROR(AVERAGEIFS(PO_Lines!$V$2:$V$2025,PO_Lines!$C$2:$C$2025,A13,PO_Lines!$V$2:$V$2025,">0"),0) | L13: =IFERROR(SUMIFS(PO_Lines!$I$2:$I$2025,PO_Lines!$C$2:$C$2025,A13)/SUMIFS(PO_Lines!$H$2:$H$2025,PO_Lines!$C$2:$C$2025,A13),0) | M13: =IFERROR(AVERAGEIFS(PO_Lines!$R$2:$R$2025,PO_Lines!$C$2:$C$2025,A13,PO_Lines!$Q$2:$Q$2025,1),0) | N13: =IF(J13>=Assumptions!$B$14,"Preferred",IF(J13>=Assumptions!$B$15,"Approved","Improvement plan"))
A14: S10 | B14: Nordic Passive Components | C14: Sweden | D14: =COUNTIF(Items!$D$2:$D$117,A14) | E14: =COUNTIFS(Items!$D$2:$D$117,A14,Items!$I$2:$I$117,TRUE) | F14: =COUNTIFS(PO_Lines!$C$2:$C$2025,A14,PO_Lines!$Q$2:$Q$2025,1) | G14: =SUMIFS(PO_Lines!$O$2:$O$2025,PO_Lines!$C$2:$C$2025,A14,PO_Lines!$D$2:$D$2025,">="&Assumptions!$B$13) | H14: =IFERROR(SUMIFS(PO_Lines!$S$2:$S$2025,PO_Lines!$C$2:$C$2025,A14)/F14,0) | I14: =IFERROR(SUMIFS(PO_Lines!$T$2:$T$2025,PO_Lines!$C$2:$C$2025,A14)/F14,0) | J14: =IFERROR(SUMIFS(PO_Lines!$U$2:$U$2025,PO_Lines!$C$2:$C$2025,A14)/F14,0) | K14: =IFERROR(AVERAGEIFS(PO_Lines!$V$2:$V$2025,PO_Lines!$C$2:$C$2025,A14,PO_Lines!$V$2:$V$2025,">0"),0) | L14: =IFERROR(SUMIFS(PO_Lines!$I$2:$I$2025,PO_Lines!$C$2:$C$2025,A14)/SUMIFS(PO_Lines!$H$2:$H$2025,PO_Lines!$C$2:$C$2025,A14),0) | M14: =IFERROR(AVERAGEIFS(PO_Lines!$R$2:$R$2025,PO_Lines!$C$2:$C$2025,A14,PO_Lines!$Q$2:$Q$2025,1),0) | N14: =IF(J14>=Assumptions!$B$14,"Preferred",IF(J14>=Assumptions!$B$15,"Approved","Improvement plan"))
A15: S11 | B15: Kyushu Semiconductor KK | C15: Japan | D15: =COUNTIF(Items!$D$2:$D$117,A15) | E15: =COUNTIFS(Items!$D$2:$D$117,A15,Items!$I$2:$I$117,TRUE) | F15: =COUNTIFS(PO_Lines!$C$2:$C$2025,A15,PO_Lines!$Q$2:$Q$2025,1) | G15: =SUMIFS(PO_Lines!$O$2:$O$2025,PO_Lines!$C$2:$C$2025,A15,PO_Lines!$D$2:$D$2025,">="&Assumptions!$B$13) | H15: =IFERROR(SUMIFS(PO_Lines!$S$2:$S$2025,PO_Lines!$C$2:$C$2025,A15)/F15,0) | I15: =IFERROR(SUMIFS(PO_Lines!$T$2:$T$2025,PO_Lines!$C$2:$C$2025,A15)/F15,0) | J15: =IFERROR(SUMIFS(PO_Lines!$U$2:$U$2025,PO_Lines!$C$2:$C$2025,A15)/F15,0) | K15: =IFERROR(AVERAGEIFS(PO_Lines!$V$2:$V$2025,PO_Lines!$C$2:$C$2025,A15,PO_Lines!$V$2:$V$2025,">0"),0) | L15: =IFERROR(SUMIFS(PO_Lines!$I$2:$I$2025,PO_Lines!$C$2:$C$2025,A15)/SUMIFS(PO_Lines!$H$2:$H$2025,PO_Lines!$C$2:$C$2025,A15),0) | M15: =IFERROR(AVERAGEIFS(PO_Lines!$R$2:$R$2025,PO_Lines!$C$2:$C$2025,A15,PO_Lines!$Q$2:$Q$2025,1),0) | N15: =IF(J15>=Assumptions!$B$14,"Preferred",IF(J15>=Assumptions!$B$15,"Approved","Improvement plan"))
A16: S12 | B16: Dublin Sterile Packaging | C16: Ireland | D16: =COUNTIF(Items!$D$2:$D$117,A16) | E16: =COUNTIFS(Items!$D$2:$D$117,A16,Items!$I$2:$I$117,TRUE) | F16: =COUNTIFS(PO_Lines!$C$2:$C$2025,A16,PO_Lines!$Q$2:$Q$2025,1) | G16: =SUMIFS(PO_Lines!$O$2:$O$2025,PO_Lines!$C$2:$C$2025,A16,PO_Lines!$D$2:$D$2025,">="&Assumptions!$B$13) | H16: =IFERROR(SUMIFS(PO_Lines!$S$2:$S$2025,PO_Lines!$C$2:$C$2025,A16)/F16,0) | I16: =IFERROR(SUMIFS(PO_Lines!$T$2:$T$2025,PO_Lines!$C$2:$C$2025,A16)/F16,0) | J16: =IFERROR(SUMIFS(PO_Lines!$U$2:$U$2025,PO_Lines!$C$2:$C$2025,A16)/F16,0) | K16: =IFERROR(AVERAGEIFS(PO_Lines!$V$2:$V$2025,PO_Lines!$C$2:$C$2025,A16,PO_Lines!$V$2:$V$2025,">0"),0) | L16: =IFERROR(SUMIFS(PO_Lines!$I$2:$I$2025,PO_Lines!$C$2:$C$2025,A16)/SUMIFS(PO_Lines!$H$2:$H$2025,PO_Lines!$C$2:$C$2025,A16),0) | M16: =IFERROR(AVERAGEIFS(PO_Lines!$R$2:$R$2025,PO_Lines!$C$2:$C$2025,A16,PO_Lines!$Q$2:$Q$2025,1),0) | N16: =IF(J16>=Assumptions!$B$14,"Preferred",IF(J16>=Assumptions!$B$15,"Approved","Improvement plan"))
A17: Total / weighted | D17: =SUM(D5:D16) | E17: =SUM(E5:E16) | F17: =SUM(F5:F16) | G17: =SUM(G5:G16) | H17: =SUMPRODUCT(H5:H16,$F$5:$F$16)/$F$17 | I17: =SUMPRODUCT(I5:I16,$F$5:$F$16)/$F$17 | J17: =SUMPRODUCT(J5:J16,$F$5:$F$16)/$F$17
A19: OTIF = share of received POs delivered on or before the promised date AND in full. Rating thresholds are on the Assumptions sheet.

Sheet Budget_vs_Actual
A1: Purchasing Budget vs Actual: FY Oct-2025 to Sep-2026
A2: Budget = planned purchases at standard cost. Actual = PO value at actual price (formulas on PO_Lines).
A4: Budget (€)
A5: Category | B5: 2025-10 | C5: 2025-11 | D5: 2025-12 | E5: 2026-01 | F5: 2026-02 | G5: 2026-03 | H5: 2026-04 | I5: 2026-05 | J5: 2026-06 | K5: 2026-07 | L5: 2026-08 | M5: 2026-09 | N5: FY total
A6: Microcontrollers & ICs | B6: 753100 | C6: 701200 | D6: 701700 | E6: 654900 | F6: 843400 | G6: 907100 | H6: 875900 | I6: 886700 | J6: 1036100 | K6: 1021100 | L6: 721700 | M6: 987800 | N6: =SUM(B6:M6)
A7: Sensors | B7: 791200 | C7: 736600 | D7: 737200 | E7: 687900 | F7: 886000 | G7: 952900 | H7: 920200 | I7: 931500 | J7: 1088400 | K7: 1072700 | L7: 758100 | M7: 1037700 | N7: =SUM(B7:M7)
A8: Printed circuit boards | B8: 275600 | C8: 256600 | D8: 256800 | E8: 239600 | F8: 308600 | G8: 331900 | H8: 320500 | I8: 324500 | J8: 379100 | K8: 373600 | L8: 264100 | M8: 361400 | N8: =SUM(B8:M8)
A9: Batteries | B9: 222600 | C9: 207200 | D9: 207400 | E9: 193500 | F9: 249200 | G9: 268100 | H9: 258900 | I9: 262100 | J9: 306200 | K9: 301800 | L9: 213300 | M9: 291900 | N9: =SUM(B9:M9)
A10: Passive components | B10: 129200 | C10: 120300 | D10: 120400 | E10: 112400 | F10: 144700 | G10: 155700 | H10: 150300 | I10: 152200 | J10: 177800 | K10: 175200 | L10: 123800 | M10: 169500 | N10: =SUM(B10:M10)
A11: Connectors & cables | B11: 135900 | C11: 126500 | D11: 126600 | E11: 118200 | F11: 152200 | G11: 163700 | H11: 158100 | I11: 160000 | J11: 187000 | K11: 184300 | L11: 130200 | M11: 178300 | N11: =SUM(B11:M11)
A12: Displays | B12: 116400 | C12: 108400 | D12: 108500 | E12: 101200 | F12: 130400 | G12: 140200 | H12: 135400 | I12: 137100 | J12: 160200 | K12: 157900 | L12: 111600 | M12: 152700 | N12: =SUM(B12:M12)
A13: Enclosures & plastics | B13: 84100 | C13: 78300 | D13: 78300 | E13: 73100 | F13: 94100 | G13: 101200 | H13: 97800 | I13: 99000 | J13: 115700 | K13: 114000 | L13: 80600 | M13: 110300 | N13: =SUM(B13:M13)
A14: Sterile packaging | B14: 17400 | C14: 16200 | D14: 16200 | E14: 15100 | F14: 19500 | G14: 21000 | H14: 20200 | I14: 20500 | J14: 23900 | K14: 23600 | L14: 16700 | M14: 22800 | N14: =SUM(B14:M14)
A15: Total | B15: =SUM(B6:B14) | C15: =SUM(C6:C14) | D15: =SUM(D6:D14) | E15: =SUM(E6:E14) | F15: =SUM(F6:F14) | G15: =SUM(G6:G14) | H15: =SUM(H6:H14) | I15: =SUM(I6:I14) | ... N15: =SUM(N6:N14)
A18: Actual (€)
A19: Category | B19: 2025-10 | C19: 2025-11 | D19: 2025-12 | E19: 2026-01 | F19: 2026-02 | G19: 2026-03 | H19: 2026-04 | I19: 2026-05 | J19: 2026-06 | K19: 2026-07 | L19: 2026-08 | M19: 2026-09 | N19: FY total
